Workbook

Sheet Описание
A1: Фаза 1. Выбор концепции проекта: чёткий коллективный метод анализа иерархий (МАИ)
A2: Команда: Пашинский П., Колесникова А., Степаненко А.
A4: Легенда
A5: Синий шрифт — суждения экспертов (шкала Саати) и справочные константы; можно менять
A6: Чёрный шрифт — формулы. Зелёный шрифт — прямые ссылки на другие листы. Жёлтая заливка — полученные приоритеты (веса).
A8: Шкала Саати для парных сравнений
A9: 1 — равноценны; 3 — умеренное превосходство; 5 — существенное; 7 — значительное; 9 — абсолютное; 2, 4, 6, 8 — промежуточные значения.
A11: Критерии
A12: Код | B12: Критерий | C12: Тип (B — выгода, C — затраты)
A13: C1 | B13: Практическая польза | C13: B
A14: C2 | B14: Сложность реализации | C14: C
A15: C3 | B15: Технические риски | C15: C
A16: C4 | B16: Чёткость границ (10-15 юз-кейсов) | C16: B
A17: C5 | B17: Интерес команды | C17: B
A18: C6 | B18: Затраты на поддержку и инфраструктуру | C18: C
A20: Альтернативы
A21: Код | B21: Название
A22: A1 | B22: Дашборд мониторинга инфраструктуры
A23: A2 | B23: Менеджер секретов и конфигов
A24: A3 | B24: Трекер техдолга и задач
A25: A4 | B25: Бот уведомлений CI/CD
A26: A5 | B26: Каталог внутренней документации

Sheet Итог
A1: Итог МАИ: глобальные приоритеты альтернатив
B3: C1 | C3: C2 | D3: C3 | E3: C4 | F3: C5 | G3: C6 | H3: Глобальный приоритет | I3: Место
A4: Вес критерия (коллективный) | B4: =Критерии!I53 -> 0.19121884 | C4: =Критерии!I54 -> 0.19121884 | D4: =Критерии!I55 -> 0.1639212 | E4: =Критерии!I56 -> 0.17035662 | F4: =Критерии!I57 -> 0.17423759 | G4: =Критерии!I58 -> 0.10904692 | H4: =SUM(B4:G4) -> 1
A5: A1 Дашборд мониторинга инфраструктуры | B5: =Альт_C1!H51 -> 0.22865084 | C5: =Альт_C2!H51 -> 0.1386806 | D5: =Альт_C3!H51 -> 0.16376089 | E5: =Альт_C4!H51 -> 0.1813364 | F5: =Альт_C5!H51 -> 0.27970417 | G5: =Альт_C6!H51 -> 0.13590822 | H5: =SUMPRODUCT($B$4:$G$4,B5:G5) -> 0.19153178 | I5: =RANK(H5,$H$5:$H$9) -> 4
A6: A2 Менеджер секретов и конфигов | B6: =Альт_C1!H52 -> 0.21832533 | C6: =Альт_C2!H52 -> 0.1042782 | D6: =Альт_C3!H52 -> 0.098847065 | E6: =Альт_C4!H52 -> 0.17314754 | F6: =Альт_C5!H52 -> 0.22200135 | G6: =Альт_C6!H52 -> 0.11515964 | H6: =SUMPRODUCT($B$4:$G$4,B6:G6) -> 0.15862662 | I6: =RANK(H6,$H$5:$H$9) -> 5
A7: A3 Трекер техдолга и задач | B7: =Альт_C1!H53 -> 0.18148029 | C7: =Альт_C2!H53 -> 0.17006683 | D7: =Альт_C3!H53 -> 0.21197905 | E7: =Альт_C4!H53 -> 0.22846955 | F7: =Альт_C5!H53 -> 0.14646627 | G7: =Альт_C6!H53 -> 0.23662995 | H7: =SUMPRODUCT($B$4:$G$4,B7:G7) -> 0.19221529 | I7: =RANK(H7,$H$5:$H$9) -> 3
A8: A4 Бот уведомлений CI/CD | B8: =Альт_C1!H54 -> 0.18148029 | C8: =Альт_C2!H54 -> 0.34551742 | D8: =Альт_C3!H54 -> 0.24349999 | E8: =Альт_C4!H54 -> 0.19889429 | F8: =Альт_C5!H54 -> 0.21197612 | G8: =Альт_C6!H54 -> 0.30630385 | H8: =SUMPRODUCT($B$4:$G$4,B8:G8) -> 0.24490536 | I8: =RANK(H8,$H$5:$H$9) -> 1
A9: A5 Каталог внутренней документации | B9: =Альт_C1!H55 -> 0.19006324 | C9: =Альт_C2!H55 -> 0.24145695 | D9: =Альт_C3!H55 -> 0.281913 | E9: =Альт_C4!H55 -> 0.21815223 | F9: =Альт_C5!H55 -> 0.13985209 | G9: =Альт_C6!H55 -> 0.20599834 | H9: =SUMPRODUCT($B$4:$G$4,B9:G9) -> 0.21272096 | I9: =RANK(H9,$H$5:$H$9) -> 2
A11: Победившая концепция по МАИ: | B11: =INDEX(A5:A9,MATCH(1,I5:I9,0)) -> A4 Бот уведомлений CI/CD
A13: Проверка согласованности (CR коллективных матриц, норма ≤ 0,10)
A14: Матрица | B14: CR
A15: Критерии | B15: =Критерии!B64 -> 0.0059857081
A16: Альтернативы по C1 | B16: =Альт_C1!B61 -> 0.0037238109
A17: Альтернативы по C2 | B17: =Альт_C2!B61 -> 0.0069957247
A18: Альтернативы по C3 | B18: =Альт_C3!B61 -> 0.0047704287
A19: Альтернативы по C4 | B19: =Альт_C4!B61 -> 0.0043064179
A20: Альтернативы по C5 | B20: =Альт_C5!B61 -> 0.001326434
A21: Альтернативы по C6 | B21: =Альт_C6!B61 -> 0.0055938917

Sheet Критерии
A1: Парные сравнения критериев (важность): эксперты и коллективная матрица
A3: Эксперт: Пашинский П.
B4: C1 | C4: C2 | D4: C3 | E4: C4 | F4: C5 | G4: C6 | H4: Геом. среднее строки | I4: Приоритет (вес)
A5: C1 Практическая польза | B5: 1 | C5: 1 | D5: 1 | E5: 2 | F5: 1 | G5: 2 | H5: =GEOMEAN(B5:G5) -> 1.259921 | I5: =H5/SUM(H$5:H$10) -> 0.20359309
A6: C2 Сложность реализации | B6: =1/C5 -> 1 | C6: 1 | D6: 1 | E6: 1 | F6: 1 | G6: 2 | H6: =GEOMEAN(B6:G6) -> 1.122462 | I6: =H6/SUM(H$5:H$10) -> 0.18138083
A7: C3 Технические риски | B7: =1/D5 -> 1 | C7: =1/D6 -> 1 | D7: 1 | E7: 2 | F7: 1 | G7: 2 | H7: =GEOMEAN(B7:G7) -> 1.259921 | I7: =H7/SUM(H$5:H$10) -> 0.20359309
A8: C4 Чёткость границ (10-15 юз-кейсов) | B8: =1/E5 -> 0.5 | C8: =1/E6 -> 1 | D8: =1/E7 -> 0.5 | E8: 1 | F8: 1 | G8: 1 | H8: =GEOMEAN(B8:G8) -> 0.79370053 | I8: =H8/SUM(H$5:H$10) -> 0.12825561
A9: C5 Интерес команды | B9: =1/F5 -> 1 | C9: =1/F6 -> 1 | D9: =1/F7 -> 1 | E9: =1/F8 -> 1 | F9: 1 | G9: 2 | H9: =GEOMEAN(B9:G9) -> 1.122462 | I9: =H9/SUM(H$5:H$10) -> 0.18138083
A10: C6 Затраты на поддержку и инфраструктуру | B10: =1/G5 -> 0.5 | C10: =1/G6 -> 0.5 | D10: =1/G7 -> 0.5 | E10: =1/G8 -> 1 | F10: =1/G9 -> 0.5 | G10: 1 | H10: =GEOMEAN(B10:G10) -> 0.62996052 | I10: =H10/SUM(H$5:H$10) -> 0.10179655
A11: Сумма столбца | B11: =SUM(B5:B10) -> 5 | C11: =SUM(C5:C10) -> 5.5 | D11: =SUM(D5:D10) -> 5 | E11: =SUM(E5:E10) -> 8 | F11: =SUM(F5:F10) -> 5.5 | G11: =SUM(G5:G10) -> 10
A12: Приоритет (в строку) | B12: =I5 -> 0.20359309 | C12: =I6 -> 0.18138083 | D12: =I7 -> 0.20359309 | E12: =I8 -> 0.12825561 | F12: =I9 -> 0.18138083 | G12: =I10 -> 0.10179655
A13: λmax = Σ(сумма столбца × приоритет) | B13: =SUMPRODUCT(B11:G11,B12:G12) -> 6.0751304
A14: CI = (λmax − n) / (n − 1) | B14: =(B13-6)/(6-1) -> 0.01502608
A15: RI (случайный индекс, таблица Саати) | B15: 1.24
A16: CR = CI / RI (норма: ≤ 0,10) | B16: =B14/B15 -> 0.012117806
A19: Эксперт: Колесникова А.
B20: C1 | C20: C2 | D20: C3 | E20: C4 | F20: C5 | G20: C6 | H20: Геом. среднее строки | I20: Приоритет (вес)
A21: C1 Практическая польза | B21: 1 | C21: 1 | D21: 2 | E21: 1 | F21: 1 | G21: 2 | H21: =GEOMEAN(B21:G21) -> 1.259921 | I21: =H21/SUM(H$21:H$26) -> 0.197583
A22: C2 Сложность реализации | B22: =1/C21 -> 1 | C22: 1 | D22: 1 | E22: 1 | F22: =1/2 -> 0.5 | G22: 2 | H22: =GEOMEAN(B22:G22) -> 1 | I22: =H22/SUM(H$21:H$26) -> 0.15682173
A23: C3 Технические риски | B23: =1/D21 -> 0.5 | C23: =1/D22 -> 1 | D23: 1 | E23: =1/2 -> 0.5 | F23: =1/2 -> 0.5 | G23: 1 | H23: =GEOMEAN(B23:G23) -> 0.70710678 | I23: =H23/SUM(H$21:H$26) -> 0.11088971
A24: C4 Чёткость границ (10-15 юз-кейсов) | B24: =1/E21 -> 1 | C24: =1/E22 -> 1 | D24: =1/E23 -> 2 | E24: 1 | F24: =1/2 -> 0.5 | G24: 2 | H24: =GEOMEAN(B24:G24) -> 1.122462 | I24: =H24/SUM(H$21:H$26) -> 0.17602645
A25: C5 Интерес команды | B25: =1/F21 -> 1 | C25: =1/F22 -> 2 | D25: =1/F23 -> 2 | E25: =1/F24 -> 2 | F25: 1 | G25: 3 | H25: =GEOMEAN(B25:G25) -> 1.6983813 | I25: =H25/SUM(H$21:H$26) -> 0.26634311
A26: C6 Затраты на поддержку и инфраструктуру | B26: =1/G21 -> 0.5 | C26: =1/G22 -> 0.5 | D26: =1/G23 -> 1 | E26: =1/G24 -> 0.5 | F26: =1/G25 -> 0.33333333 | G26: 1 | H26: =GEOMEAN(B26:G26) -> 0.58879592 | I26: =H26/SUM(H$21:H$26) -> 0.092335998
A27: Сумма столбца | B27: =SUM(B21:B26) -> 5 | C27: =SUM(C21:C26) -> 6.5 | D27: =SUM(D21:D26) -> 9 | E27: =SUM(E21:E26) -> 6 | F27: =SUM(F21:F26) -> 3.8333333 | G27: =SUM(G21:G26) -> 11
A28: Приоритет (в строку) | B28: =I21 -> 0.197583 | C28: =I22 -> 0.15682173 | D28: =I23 -> 0.11088971 | E28: =I24 -> 0.17602645 | F28: =I25 -> 0.26634311 | G28: =I26 -> 0.092335998
A29: λmax = Σ(сумма столбца × приоритет) | B29: =SUMPRODUCT(B27:G27,B28:G28) -> 6.0981003
A30: CI = (λmax − n) / (n − 1) | B30: =(B29-6)/(6-1) -> 0.019620051
A31: RI (случайный индекс, таблица Саати) | B31: 1.24
A32: CR = CI / RI (норма: ≤ 0,10) | B32: =B30/B31 -> 0.015822622
A35: Эксперт: Степаненко А.
B36: C1 | C36: C2 | D36: C3 | E36: C4 | F36: C5 | G36: C6 | H36: Геом. среднее строки | I36: Приоритет (вес)
A37: C1 Практическая польза | B37: 1 | C37: =1/2 -> 0.5 | D37: 1 | E37: 1 | F37: 2 | G37: 1 | H37: =GEOMEAN(B37:G37) -> 1 | I37: =H37/SUM(H$37:H$42) -> 0.16076504
A38: C2 Сложность реализации | B38: =1/C37 -> 2 | C38: 1 | D38: 1 | E38: 1 | F38: 2 | G38: 2 | H38: =GEOMEAN(B38:G38) -> 1.4142136 | I38: =H38/SUM(H$37:H$42) -> 0.2273561
A39: C3 Технические риски | B39: =1/D37 -> 1 | C39: =1/D38 -> 1 | D39: 1 | E39: 1 | F39: 2 | G39: 1 | H39: =GEOMEAN(B39:G39) -> 1.122462 | I39: =H39/SUM(H$37:H$42) -> 0.18045266
A40: C4 Чёткость границ (10-15 юз-кейсов) | B40: =1/E37 -> 1 | C40: =1/E38 -> 1 | D40: =1/E39 -> 1 | E40: 1 | F40: 2 | G40: 2 | H40: =GEOMEAN(B40:G40) -> 1.259921 | I40: =H40/SUM(H$37:H$42) -> 0.20255126
A41: C5 Интерес команды | B41: =1/F37 -> 0.5 | C41: =1/F38 -> 0.5 | D41: =1/F39 -> 0.5 | E41: =1/F40 -> 0.5 | F41: 1 | G41: 1 | H41: =GEOMEAN(B41:G41) -> 0.62996052 | I41: =H41/SUM(H$37:H$42) -> 0.10127563
A42: C6 Затраты на поддержку и инфраструктуру | B42: =1/G37 -> 1 | C42: =1/G38 -> 0.5 | D42: =1/G39 -> 1 | E42: =1/G40 -> 0.5 | F42: =1/G41 -> 1 | G42: 1 | H42: =GEOMEAN(B42:G42) -> 0.79370053 | I42: =H42/SUM(H$37:H$42) -> 0.1275993
A43: Сумма столбца | B43: =SUM(B37:B42) -> 6.5 | C43: =SUM(C37:C42) -> 4.5 | D43: =SUM(D37:D42) -> 5.5 | E43: =SUM(E37:E42) -> 5 | F43: =SUM(F37:F42) -> 10 | G43: =SUM(G37:G42) -> 8
A44: Приоритет (в строку) | B44: =I37 -> 0.16076504 | C44: =I38 -> 0.2273561 | D44: =I39 -> 0.18045266 | E44: =I40 -> 0.20255126 | F44: =I41 -> 0.10127563 | G44: =I42 -> 0.1275993
A45: λmax = Σ(сумма столбца × приоритет) | B45: =SUMPRODUCT(B43:G43,B44:G44) -> 6.1068719
...

Sheet Альт_C1
A1: Парные сравнения альтернатив по критерию: C1 Практическая польза
A2: Критерий типа B: сравниваем, какая альтернатива лучше по этому критерию.
A4: Эксперт: Пашинский П.
B5: A1 | C5: A2 | D5: A3 | E5: A4 | F5: A5 | G5: Геом. среднее строки | H5: Приоритет (вес)
A6: A1 Дашборд мониторинга инфраструктуры | B6: 1 | C6: 1 | D6: 2 | E6: 1 | F6: 2 | G6: =GEOMEAN(B6:F6) -> 1.3195079 | H6: =G6/SUM(G$6:G$10) -> 0.25597991
A7: A2 Менеджер секретов и конфигов | B7: =1/C6 -> 1 | C7: 1 | D7: 2 | E7: 1 | F7: 2 | G7: =GEOMEAN(B7:F7) -> 1.3195079 | H7: =G7/SUM(G$6:G$10) -> 0.25597991
A8: A3 Трекер техдолга и задач | B8: =1/D6 -> 0.5 | C8: =1/D7 -> 0.5 | D8: 1 | E8: 1 | F8: 1 | G8: =GEOMEAN(B8:F8) -> 0.75785828 | H8: =G8/SUM(G$6:G$10) -> 0.14702185
A9: A4 Бот уведомлений CI/CD | B9: =1/E6 -> 1 | C9: =1/E7 -> 1 | D9: =1/E8 -> 1 | E9: 1 | F9: 1 | G9: =GEOMEAN(B9:F9) -> 1 | H9: =G9/SUM(G$6:G$10) -> 0.19399649
A10: A5 Каталог внутренней документации | B10: =1/F6 -> 0.5 | C10: =1/F7 -> 0.5 | D10: =1/F8 -> 1 | E10: =1/F9 -> 1 | F10: 1 | G10: =GEOMEAN(B10:F10) -> 0.75785828 | H10: =G10/SUM(G$6:G$10) -> 0.14702185
A11: Сумма столбца | B11: =SUM(B6:B10) -> 4 | C11: =SUM(C6:C10) -> 4 | D11: =SUM(D6:D10) -> 7 | E11: =SUM(E6:E10) -> 5 | F11: =SUM(F6:F10) -> 7
A12: Приоритет (в строку) | B12: =H6 -> 0.25597991 | C12: =H7 -> 0.25597991 | D12: =H8 -> 0.14702185 | E12: =H9 -> 0.19399649 | F12: =H10 -> 0.14702185
A13: λmax = Σ(сумма столбца × приоритет) | B13: =SUMPRODUCT(B11:F11,B12:F12) -> 5.0761276
A14: CI = (λmax − n) / (n − 1) | B14: =(B13-5)/(5-1) -> 0.019031895
A15: RI (случайный индекс, таблица Саати) | B15: 1.12
A16: CR = CI / RI (норма: ≤ 0,10) | B16: =B14/B15 -> 0.016992764
A19: Эксперт: Колесникова А.
B20: A1 | C20: A2 | D20: A3 | E20: A4 | F20: A5 | G20: Геом. среднее строки | H20: Приоритет (вес)
A21: A1 Дашборд мониторинга инфраструктуры | B21: 1 | C21: 1 | D21: 1 | E21: 2 | F21: 1 | G21: =GEOMEAN(B21:F21) -> 1.1486984 | H21: =G21/SUM(G$21:G$25) -> 0.22722857
A22: A2 Менеджер секретов и конфигов | B22: =1/C21 -> 1 | C22: 1 | D22: 1 | E22: 1 | F22: 1 | G22: =GEOMEAN(B22:F22) -> 1 | H22: =G22/SUM(G$21:G$25) -> 0.19781396
A23: A3 Трекер техдолга и задач | B23: =1/D21 -> 1 | C23: =1/D22 -> 1 | D23: 1 | E23: 1 | F23: 1 | G23: =GEOMEAN(B23:F23) -> 1 | H23: =G23/SUM(G$21:G$25) -> 0.19781396
A24: A4 Бот уведомлений CI/CD | B24: =1/E21 -> 0.5 | C24: =1/E22 -> 1 | D24: =1/E23 -> 1 | E24: 1 | F24: =1/2 -> 0.5 | G24: =GEOMEAN(B24:F24) -> 0.75785828 | H24: =G24/SUM(G$21:G$25) -> 0.14991495
A25: A5 Каталог внутренней документации | B25: =1/F21 -> 1 | C25: =1/F22 -> 1 | D25: =1/F23 -> 1 | E25: =1/F24 -> 2 | F25: 1 | G25: =GEOMEAN(B25:F25) -> 1.1486984 | H25: =G25/SUM(G$21:G$25) -> 0.22722857
A26: Сумма столбца | B26: =SUM(B21:B25) -> 4.5 | C26: =SUM(C21:C25) -> 5 | D26: =SUM(D21:D25) -> 5 | E26: =SUM(E21:E25) -> 7 | F26: =SUM(F21:F25) -> 4.5
A27: Приоритет (в строку) | B27: =H21 -> 0.22722857 | C27: =H22 -> 0.19781396 | D27: =H23 -> 0.19781396 | E27: =H24 -> 0.14991495 | F27: =H25 -> 0.22722857
A28: λmax = Σ(сумма столбца × приоритет) | B28: =SUMPRODUCT(B26:F26,B27:F27) -> 5.0726013
A29: CI = (λmax − n) / (n − 1) | B29: =(B28-5)/(5-1) -> 0.018150331
A30: RI (случайный индекс, таблица Саати) | B30: 1.12
A31: CR = CI / RI (норма: ≤ 0,10) | B31: =B29/B30 -> 0.016205653
A34: Эксперт: Степаненко А.
B35: A1 | C35: A2 | D35: A3 | E35: A4 | F35: A5 | G35: Геом. среднее строки | H35: Приоритет (вес)
A36: A1 Дашборд мониторинга инфраструктуры | B36: 1 | C36: 1 | D36: 1 | E36: 1 | F36: 1 | G36: =GEOMEAN(B36:F36) -> 1 | H36: =G36/SUM(G$36:G$40) -> 0.2
A37: A2 Менеджер секретов и конфигов | B37: =1/C36 -> 1 | C37: 1 | D37: 1 | E37: 1 | F37: 1 | G37: =GEOMEAN(B37:F37) -> 1 | H37: =G37/SUM(G$36:G$40) -> 0.2
A38: A3 Трекер техдолга и задач | B38: =1/D36 -> 1 | C38: =1/D37 -> 1 | D38: 1 | E38: 1 | F38: 1 | G38: =GEOMEAN(B38:F38) -> 1 | H38: =G38/SUM(G$36:G$40) -> 0.2
A39: A4 Бот уведомлений CI/CD | B39: =1/E36 -> 1 | C39: =1/E37 -> 1 | D39: =1/E38 -> 1 | E39: 1 | F39: 1 | G39: =GEOMEAN(B39:F39) -> 1 | H39: =G39/SUM(G$36:G$40) -> 0.2
A40: A5 Каталог внутренней документации | B40: =1/F36 -> 1 | C40: =1/F37 -> 1 | D40: =1/F38 -> 1 | E40: =1/F39 -> 1 | F40: 1 | G40: =GEOMEAN(B40:F40) -> 1 | H40: =G40/SUM(G$36:G$40) -> 0.2
A41: Сумма столбца | B41: =SUM(B36:B40) -> 5 | C41: =SUM(C36:C40) -> 5 | D41: =SUM(D36:D40) -> 5 | E41: =SUM(E36:E40) -> 5 | F41: =SUM(F36:F40) -> 5
A42: Приоритет (в строку) | B42: =H36 -> 0.2 | C42: =H37 -> 0.2 | D42: =H38 -> 0.2 | E42: =H39 -> 0.2 | F42: =H40 -> 0.2
A43: λmax = Σ(сумма столбца × приоритет) | B43: =SUMPRODUCT(B41:F41,B42:F42) -> 5
A44: CI = (λmax − n) / (n − 1) | B44: =(B43-5)/(5-1) -> 0
A45: RI (случайный индекс, таблица Саати) | B45: 1.12
...

Sheet Альт_C2
A1: Парные сравнения альтернатив по критерию: C2 Сложность реализации
A2: Критерий типа C: сравниваем, какая альтернатива лучше, то есть менее затратная / менее сложная / менее рискованная.
A4: Эксперт: Пашинский П.
B5: A1 | C5: A2 | D5: A3 | E5: A4 | F5: A5 | G5: Геом. среднее строки | H5: Приоритет (вес)
A6: A1 Дашборд мониторинга инфраструктуры | B6: 1 | C6: 1 | D6: 1 | E6: =1/2 -> 0.5 | F6: =1/2 -> 0.5 | G6: =GEOMEAN(B6:F6) -> 0.75785828 | H6: =G6/SUM(G$6:G$10) -> 0.14220111
A7: A2 Менеджер секретов и конфигов | B7: =1/C6 -> 1 | C7: 1 | D7: =1/2 -> 0.5 | E7: =1/3 -> 0.33333333 | F7: =1/2 -> 0.5 | G7: =GEOMEAN(B7:F7) -> 0.60836434 | H7: =G7/SUM(G$6:G$10) -> 0.11415074
A8: A3 Трекер техдолга и задач | B8: =1/D6 -> 1 | C8: =1/D7 -> 2 | D8: 1 | E8: =1/2 -> 0.5 | F8: 1 | G8: =GEOMEAN(B8:F8) -> 1 | H8: =G8/SUM(G$6:G$10) -> 0.18763548
A9: A4 Бот уведомлений CI/CD | B9: =1/E6 -> 2 | C9: =1/E7 -> 3 | D9: =1/E8 -> 2 | E9: 1 | F9: 1 | G9: =GEOMEAN(B9:F9) -> 1.6437518 | H9: =G9/SUM(G$6:G$10) -> 0.30842617
A10: A5 Каталог внутренней документации | B10: =1/F6 -> 2 | C10: =1/F7 -> 2 | D10: =1/F8 -> 1 | E10: =1/F9 -> 1 | F10: 1 | G10: =GEOMEAN(B10:F10) -> 1.3195079 | H10: =G10/SUM(G$6:G$10) -> 0.2475865
A11: Сумма столбца | B11: =SUM(B6:B10) -> 7 | C11: =SUM(C6:C10) -> 9 | D11: =SUM(D6:D10) -> 5.5 | E11: =SUM(E6:E10) -> 3.3333333 | F11: =SUM(F6:F10) -> 4
A12: Приоритет (в строку) | B12: =H6 -> 0.14220111 | C12: =H7 -> 0.11415074 | D12: =H8 -> 0.18763548 | E12: =H9 -> 0.30842617 | F12: =H10 -> 0.2475865
A13: λmax = Σ(сумма столбца × приоритет) | B13: =SUMPRODUCT(B11:F11,B12:F12) -> 5.0731928
A14: CI = (λmax − n) / (n − 1) | B14: =(B13-5)/(5-1) -> 0.018298195
A15: RI (случайный индекс, таблица Саати) | B15: 1.12
A16: CR = CI / RI (норма: ≤ 0,10) | B16: =B14/B15 -> 0.016337675
A19: Эксперт: Колесникова А.
B20: A1 | C20: A2 | D20: A3 | E20: A4 | F20: A5 | G20: Геом. среднее строки | H20: Приоритет (вес)
A21: A1 Дашборд мониторинга инфраструктуры | B21: 1 | C21: 2 | D21: 1 | E21: =1/2 -> 0.5 | F21: =1/2 -> 0.5 | G21: =GEOMEAN(B21:F21) -> 0.87055056 | H21: =G21/SUM(G$21:G$25) -> 0.16231252
A22: A2 Менеджер секретов и конфигов | B22: =1/C21 -> 0.5 | C22: 1 | D22: =1/2 -> 0.5 | E22: =1/3 -> 0.33333333 | F22: =1/2 -> 0.5 | G22: =GEOMEAN(B22:F22) -> 0.52961192 | H22: =G22/SUM(G$21:G$25) -> 0.098745148
A23: A3 Трекер техдолга и задач | B23: =1/D21 -> 1 | C23: =1/D22 -> 2 | D23: 1 | E23: =1/2 -> 0.5 | F23: 1 | G23: =GEOMEAN(B23:F23) -> 1 | H23: =G23/SUM(G$21:G$25) -> 0.18644812
A24: A4 Бот уведомлений CI/CD | B24: =1/E21 -> 2 | C24: =1/E22 -> 3 | D24: =1/E23 -> 2 | E24: 1 | F24: 1 | G24: =GEOMEAN(B24:F24) -> 1.6437518 | H24: =G24/SUM(G$21:G$25) -> 0.30647444
A25: A5 Каталог внутренней документации | B25: =1/F21 -> 2 | C25: =1/F22 -> 2 | D25: =1/F23 -> 1 | E25: =1/F24 -> 1 | F25: 1 | G25: =GEOMEAN(B25:F25) -> 1.3195079 | H25: =G25/SUM(G$21:G$25) -> 0.24601977
A26: Сумма столбца | B26: =SUM(B21:B25) -> 6.5 | C26: =SUM(C21:C25) -> 10 | D26: =SUM(D21:D25) -> 5.5 | E26: =SUM(E21:E25) -> 3.3333333 | F26: =SUM(F21:F25) -> 4
A27: Приоритет (в строку) | B27: =H21 -> 0.16231252 | C27: =H22 -> 0.098745148 | D27: =H23 -> 0.18644812 | E27: =H24 -> 0.30647444 | F27: =H25 -> 0.24601977
A28: λmax = Σ(сумма столбца × приоритет) | B28: =SUMPRODUCT(B26:F26,B27:F27) -> 5.0736081
A29: CI = (λmax − n) / (n − 1) | B29: =(B28-5)/(5-1) -> 0.018402017
A30: RI (случайный индекс, таблица Саати) | B30: 1.12
A31: CR = CI / RI (норма: ≤ 0,10) | B31: =B29/B30 -> 0.016430373
A34: Эксперт: Степаненко А.
B35: A1 | C35: A2 | D35: A3 | E35: A4 | F35: A5 | G35: Геом. среднее строки | H35: Приоритет (вес)
A36: A1 Дашборд мониторинга инфраструктуры | B36: 1 | C36: 1 | D36: 1 | E36: =1/4 -> 0.25 | F36: =1/2 -> 0.5 | G36: =GEOMEAN(B36:F36) -> 0.65975396 | H36: =G36/SUM(G$36:G$40) -> 0.1128206
A37: A2 Менеджер секретов и конфигов | B37: =1/C36 -> 1 | C37: 1 | D37: =1/2 -> 0.5 | E37: =1/4 -> 0.25 | F37: =1/2 -> 0.5 | G37: =GEOMEAN(B37:F37) -> 0.57434918 | H37: =G37/SUM(G$36:G$40) -> 0.098216039
A38: A3 Трекер техдолга и задач | B38: =1/D36 -> 1 | C38: =1/D37 -> 2 | D38: 1 | E38: =1/3 -> 0.33333333 | F38: =1/2 -> 0.5 | G38: =GEOMEAN(B38:F38) -> 0.80274156 | H38: =G38/SUM(G$36:G$40) -> 0.13727206
A39: A4 Бот уведомлений CI/CD | B39: =1/E36 -> 4 | C39: =1/E37 -> 4 | D39: =1/E38 -> 3 | E39: 1 | F39: 2 | G39: =GEOMEAN(B39:F39) -> 2.4914619 | H39: =G39/SUM(G$36:G$40) -> 0.42605009
A40: A5 Каталог внутренней документации | B40: =1/F36 -> 2 | C40: =1/F37 -> 2 | D40: =1/F38 -> 2 | E40: =1/F39 -> 0.5 | F40: 1 | G40: =GEOMEAN(B40:F40) -> 1.3195079 | H40: =G40/SUM(G$36:G$40) -> 0.22564121
A41: Сумма столбца | B41: =SUM(B36:B40) -> 9 | C41: =SUM(C36:C40) -> 10 | D41: =SUM(D36:D40) -> 7.5 | E41: =SUM(E36:E40) -> 2.3333333 | F41: =SUM(F36:F40) -> 4.5
A42: Приоритет (в строку) | B42: =H36 -> 0.1128206 | C42: =H37 -> 0.098216039 | D42: =H38 -> 0.13727206 | E42: =H39 -> 0.42605009 | F42: =H40 -> 0.22564121
A43: λmax = Σ(сумма столбца × приоритет) | B43: =SUMPRODUCT(B41:F41,B42:F42) -> 5.0365886
A44: CI = (λmax − n) / (n − 1) | B44: =(B43-5)/(5-1) -> 0.0091471486
A45: RI (случайный индекс, таблица Саати) | B45: 1.12
...

Sheet Альт_C3
A1: Парные сравнения альтернатив по критерию: C3 Технические риски
A2: Критерий типа C: сравниваем, какая альтернатива лучше, то есть менее затратная / менее сложная / менее рискованная.
A4: Эксперт: Пашинский П.
B5: A1 | C5: A2 | D5: A3 | E5: A4 | F5: A5 | G5: Геом. среднее строки | H5: Приоритет (вес)
A6: A1 Дашборд мониторинга инфраструктуры | B6: 1 | C6: 2 | D6: =1/2 -> 0.5 | E6: 1 | F6: =1/2 -> 0.5 | G6: =GEOMEAN(B6:F6) -> 0.87055056 | H6: =G6/SUM(G$6:G$10) -> 0.16212739
A7: A2 Менеджер секретов и конфигов | B7: =1/C6 -> 0.5 | C7: 1 | D7: =1/3 -> 0.33333333 | E7: =1/2 -> 0.5 | F7: =1/3 -> 0.33333333 | G7: =GEOMEAN(B7:F7) -> 0.48835934 | H7: =G7/SUM(G$6:G$10) -> 0.090949831
A8: A3 Трекер техдолга и задач | B8: =1/D6 -> 2 | C8: =1/D7 -> 3 | D8: 1 | E8: 1 | F8: 1 | G8: =GEOMEAN(B8:F8) -> 1.4309691 | H8: =G8/SUM(G$6:G$10) -> 0.2664972
A9: A4 Бот уведомлений CI/CD | B9: =1/E6 -> 1 | C9: =1/E7 -> 2 | D9: =1/E8 -> 1 | E9: 1 | F9: 1 | G9: =GEOMEAN(B9:F9) -> 1.1486984 | H9: =G9/SUM(G$6:G$10) -> 0.21392838
A10: A5 Каталог внутренней документации | B10: =1/F6 -> 2 | C10: =1/F7 -> 3 | D10: =1/F8 -> 1 | E10: =1/F9 -> 1 | F10: 1 | G10: =GEOMEAN(B10:F10) -> 1.4309691 | H10: =G10/SUM(G$6:G$10) -> 0.2664972
A11: Сумма столбца | B11: =SUM(B6:B10) -> 6.5 | C11: =SUM(C6:C10) -> 11 | D11: =SUM(D6:D10) -> 3.8333333 | E11: =SUM(E6:E10) -> 4.5 | F11: =SUM(F6:F10) -> 3.8333333
A12: Приоритет (в строку) | B12: =H6 -> 0.16212739 | C12: =H7 -> 0.090949831 | D12: =H8 -> 0.2664972 | E12: =H9 -> 0.21392838 | F12: =H10 -> 0.2664972
A13: λmax = Σ(сумма столбца × приоритет) | B13: =SUMPRODUCT(B11:F11,B12:F12) -> 5.0600991
A14: CI = (λmax − n) / (n − 1) | B14: =(B13-5)/(5-1) -> 0.015024773
A15: RI (случайный индекс, таблица Саати) | B15: 1.12
A16: CR = CI / RI (норма: ≤ 0,10) | B16: =B14/B15 -> 0.013414976
A19: Эксперт: Колесникова А.
B20: A1 | C20: A2 | D20: A3 | E20: A4 | F20: A5 | G20: Геом. среднее строки | H20: Приоритет (вес)
A21: A1 Дашборд мониторинга инфраструктуры | B21: 1 | C21: 2 | D21: 1 | E21: 1 | F21: =1/2 -> 0.5 | G21: =GEOMEAN(B21:F21) -> 1 | H21: =G21/SUM(G$21:G$25) -> 0.19018719
A22: A2 Менеджер секретов и конфигов | B22: =1/C21 -> 0.5 | C22: 1 | D22: =1/2 -> 0.5 | E22: =1/2 -> 0.5 | F22: =1/3 -> 0.33333333 | G22: =GEOMEAN(B22:F22) -> 0.52961192 | H22: =G22/SUM(G$21:G$25) -> 0.1007254
A23: A3 Трекер техдолга и задач | B23: =1/D21 -> 1 | C23: =1/D22 -> 2 | D23: 1 | E23: 1 | F23: 1 | G23: =GEOMEAN(B23:F23) -> 1.1486984 | H23: =G23/SUM(G$21:G$25) -> 0.21846771
A24: A4 Бот уведомлений CI/CD | B24: =1/E21 -> 1 | C24: =1/E22 -> 2 | D24: =1/E23 -> 1 | E24: 1 | F24: 1 | G24: =GEOMEAN(B24:F24) -> 1.1486984 | H24: =G24/SUM(G$21:G$25) -> 0.21846771
A25: A5 Каталог внутренней документации | B25: =1/F21 -> 2 | C25: =1/F22 -> 3 | D25: =1/F23 -> 1 | E25: =1/F24 -> 1 | F25: 1 | G25: =GEOMEAN(B25:F25) -> 1.4309691 | H25: =G25/SUM(G$21:G$25) -> 0.27215199
A26: Сумма столбца | B26: =SUM(B21:B25) -> 5.5 | C26: =SUM(C21:C25) -> 10 | D26: =SUM(D21:D25) -> 4.5 | E26: =SUM(E21:E25) -> 4.5 | F26: =SUM(F21:F25) -> 3.8333333
A27: Приоритет (в строку) | B27: =H21 -> 0.19018719 | C27: =H22 -> 0.1007254 | D27: =H23 -> 0.21846771 | E27: =H24 -> 0.21846771 | F27: =H25 -> 0.27215199
A28: λmax = Σ(сумма столбца × приоритет) | B28: =SUMPRODUCT(B26:F26,B27:F27) -> 5.0627422
A29: CI = (λmax − n) / (n − 1) | B29: =(B28-5)/(5-1) -> 0.015685561
A30: RI (случайный индекс, таблица Саати) | B30: 1.12
A31: CR = CI / RI (норма: ≤ 0,10) | B31: =B29/B30 -> 0.014004965
A34: Эксперт: Степаненко А.
B35: A1 | C35: A2 | D35: A3 | E35: A4 | F35: A5 | G35: Геом. среднее строки | H35: Приоритет (вес)
A36: A1 Дашборд мониторинга инфраструктуры | B36: 1 | C36: 1 | D36: 1 | E36: =1/2 -> 0.5 | F36: =1/2 -> 0.5 | G36: =GEOMEAN(B36:F36) -> 0.75785828 | H36: =G36/SUM(G$36:G$40) -> 0.13837383
A37: A2 Менеджер секретов и конфигов | B37: =1/C36 -> 1 | C37: 1 | D37: =1/2 -> 0.5 | E37: =1/3 -> 0.33333333 | F37: =1/3 -> 0.33333333 | G37: =GEOMEAN(B37:F37) -> 0.56097757 | H37: =G37/SUM(G$36:G$40) -> 0.1024263
A38: A3 Трекер техдолга и задач | B38: =1/D36 -> 1 | C38: =1/D37 -> 2 | D38: 1 | E38: =1/2 -> 0.5 | F38: =1/2 -> 0.5 | G38: =GEOMEAN(B38:F38) -> 0.87055056 | H38: =G38/SUM(G$36:G$40) -> 0.1589498
A39: A4 Бот уведомлений CI/CD | B39: =1/E36 -> 2 | C39: =1/E37 -> 3 | D39: =1/E38 -> 2 | E39: 1 | F39: 1 | G39: =GEOMEAN(B39:F39) -> 1.6437518 | H39: =G39/SUM(G$36:G$40) -> 0.30012504
A40: A5 Каталог внутренней документации | B40: =1/F36 -> 2 | C40: =1/F37 -> 3 | D40: =1/F38 -> 2 | E40: =1/F39 -> 1 | F40: 1 | G40: =GEOMEAN(B40:F40) -> 1.6437518 | H40: =G40/SUM(G$36:G$40) -> 0.30012504
A41: Сумма столбца | B41: =SUM(B36:B40) -> 7 | C41: =SUM(C36:C40) -> 10 | D41: =SUM(D36:D40) -> 6.5 | E41: =SUM(E36:E40) -> 3.3333333 | F41: =SUM(F36:F40) -> 3.3333333
A42: Приоритет (в строку) | B42: =H36 -> 0.13837383 | C42: =H37 -> 0.1024263 | D42: =H38 -> 0.1589498 | E42: =H39 -> 0.30012504 | F42: =H40 -> 0.30012504
A43: λmax = Σ(сумма столбца × приоритет) | B43: =SUMPRODUCT(B41:F41,B42:F42) -> 5.0268871
A44: CI = (λmax − n) / (n − 1) | B44: =(B43-5)/(5-1) -> 0.0067217667
A45: RI (случайный индекс, таблица Саати) | B45: 1.12
...

Sheet Альт_C4
A1: Парные сравнения альтернатив по критерию: C4 Чёткость границ (10-15 юз-кейсов)
A2: Критерий типа B: сравниваем, какая альтернатива лучше по этому критерию.
A4: Эксперт: Пашинский П.
B5: A1 | C5: A2 | D5: A3 | E5: A4 | F5: A5 | G5: Геом. среднее строки | H5: Приоритет (вес)
A6: A1 Дашборд мониторинга инфраструктуры | B6: 1 | C6: 1 | D6: 1 | E6: 1 | F6: 1 | G6: =GEOMEAN(B6:F6) -> 1 | H6: =G6/SUM(G$6:G$10) -> 0.2
A7: A2 Менеджер секретов и конфигов | B7: =1/C6 -> 1 | C7: 1 | D7: 1 | E7: 1 | F7: 1 | G7: =GEOMEAN(B7:F7) -> 1 | H7: =G7/SUM(G$6:G$10) -> 0.2
A8: A3 Трекер техдолга и задач | B8: =1/D6 -> 1 | C8: =1/D7 -> 1 | D8: 1 | E8: 1 | F8: 1 | G8: =GEOMEAN(B8:F8) -> 1 | H8: =G8/SUM(G$6:G$10) -> 0.2
A9: A4 Бот уведомлений CI/CD | B9: =1/E6 -> 1 | C9: =1/E7 -> 1 | D9: =1/E8 -> 1 | E9: 1 | F9: 1 | G9: =GEOMEAN(B9:F9) -> 1 | H9: =G9/SUM(G$6:G$10) -> 0.2
A10: A5 Каталог внутренней документации | B10: =1/F6 -> 1 | C10: =1/F7 -> 1 | D10: =1/F8 -> 1 | E10: =1/F9 -> 1 | F10: 1 | G10: =GEOMEAN(B10:F10) -> 1 | H10: =G10/SUM(G$6:G$10) -> 0.2
A11: Сумма столбца | B11: =SUM(B6:B10) -> 5 | C11: =SUM(C6:C10) -> 5 | D11: =SUM(D6:D10) -> 5 | E11: =SUM(E6:E10) -> 5 | F11: =SUM(F6:F10) -> 5
A12: Приоритет (в строку) | B12: =H6 -> 0.2 | C12: =H7 -> 0.2 | D12: =H8 -> 0.2 | E12: =H9 -> 0.2 | F12: =H10 -> 0.2
A13: λmax = Σ(сумма столбца × приоритет) | B13: =SUMPRODUCT(B11:F11,B12:F12) -> 5
A14: CI = (λmax − n) / (n − 1) | B14: =(B13-5)/(5-1) -> 0
A15: RI (случайный индекс, таблица Саати) | B15: 1.12
A16: CR = CI / RI (норма: ≤ 0,10) | B16: =B14/B15 -> 0
A19: Эксперт: Колесникова А.
B20: A1 | C20: A2 | D20: A3 | E20: A4 | F20: A5 | G20: Геом. среднее строки | H20: Приоритет (вес)
A21: A1 Дашборд мониторинга инфраструктуры | B21: 1 | C21: 1 | D21: 1 | E21: 1 | F21: 1 | G21: =GEOMEAN(B21:F21) -> 1 | H21: =G21/SUM(G$21:G$25) -> 0.19781396
A22: A2 Менеджер секретов и конфигов | B22: =1/C21 -> 1 | C22: 1 | D22: =1/2 -> 0.5 | E22: 1 | F22: =1/2 -> 0.5 | G22: =GEOMEAN(B22:F22) -> 0.75785828 | H22: =G22/SUM(G$21:G$25) -> 0.14991495
A23: A3 Трекер техдолга и задач | B23: =1/D21 -> 1 | C23: =1/D22 -> 2 | D23: 1 | E23: 1 | F23: 1 | G23: =GEOMEAN(B23:F23) -> 1.1486984 | H23: =G23/SUM(G$21:G$25) -> 0.22722857
A24: A4 Бот уведомлений CI/CD | B24: =1/E21 -> 1 | C24: =1/E22 -> 1 | D24: =1/E23 -> 1 | E24: 1 | F24: 1 | G24: =GEOMEAN(B24:F24) -> 1 | H24: =G24/SUM(G$21:G$25) -> 0.19781396
A25: A5 Каталог внутренней документации | B25: =1/F21 -> 1 | C25: =1/F22 -> 2 | D25: =1/F23 -> 1 | E25: =1/F24 -> 1 | F25: 1 | G25: =GEOMEAN(B25:F25) -> 1.1486984 | H25: =G25/SUM(G$21:G$25) -> 0.22722857
A26: Сумма столбца | B26: =SUM(B21:B25) -> 5 | C26: =SUM(C21:C25) -> 7 | D26: =SUM(D21:D25) -> 4.5 | E26: =SUM(E21:E25) -> 5 | F26: =SUM(F21:F25) -> 4.5
A27: Приоритет (в строку) | B27: =H21 -> 0.19781396 | C27: =H22 -> 0.14991495 | D27: =H23 -> 0.22722857 | E27: =H24 -> 0.19781396 | F27: =H25 -> 0.22722857
A28: λmax = Σ(сумма столбца × приоритет) | B28: =SUMPRODUCT(B26:F26,B27:F27) -> 5.0726013
A29: CI = (λmax − n) / (n − 1) | B29: =(B28-5)/(5-1) -> 0.018150331
A30: RI (случайный индекс, таблица Саати) | B30: 1.12
A31: CR = CI / RI (норма: ≤ 0,10) | B31: =B29/B30 -> 0.016205653
A34: Эксперт: Степаненко А.
B35: A1 | C35: A2 | D35: A3 | E35: A4 | F35: A5 | G35: Геом. среднее строки | H35: Приоритет (вес)
A36: A1 Дашборд мониторинга инфраструктуры | B36: 1 | C36: 1 | D36: =1/2 -> 0.5 | E36: 1 | F36: =1/2 -> 0.5 | G36: =GEOMEAN(B36:F36) -> 0.75785828 | H36: =G36/SUM(G$36:G$40) -> 0.14869835
A37: A2 Менеджер секретов и конфигов | B37: =1/C36 -> 1 | C37: 1 | D37: =1/2 -> 0.5 | E37: 1 | F37: 1 | G37: =GEOMEAN(B37:F37) -> 0.87055056 | H37: =G37/SUM(G$36:G$40) -> 0.17080956
A38: A3 Трекер техдолга и задач | B38: =1/D36 -> 2 | C38: =1/D37 -> 2 | D38: 1 | E38: 1 | F38: 1 | G38: =GEOMEAN(B38:F38) -> 1.3195079 | H38: =G38/SUM(G$36:G$40) -> 0.25889887
A39: A4 Бот уведомлений CI/CD | B39: =1/E36 -> 1 | C39: =1/E37 -> 1 | D39: =1/E38 -> 1 | E39: 1 | F39: 1 | G39: =GEOMEAN(B39:F39) -> 1 | H39: =G39/SUM(G$36:G$40) -> 0.19620866
A40: A5 Каталог внутренней документации | B40: =1/F36 -> 2 | C40: =1/F37 -> 1 | D40: =1/F38 -> 1 | E40: =1/F39 -> 1 | F40: 1 | G40: =GEOMEAN(B40:F40) -> 1.1486984 | H40: =G40/SUM(G$36:G$40) -> 0.22538456
A41: Сумма столбца | B41: =SUM(B36:B40) -> 7 | C41: =SUM(C36:C40) -> 6 | D41: =SUM(D36:D40) -> 4 | E41: =SUM(E36:E40) -> 5 | F41: =SUM(F36:F40) -> 4.5
A42: Приоритет (в строку) | B42: =H36 -> 0.14869835 | C42: =H37 -> 0.17080956 | D42: =H38 -> 0.25889887 | E42: =H39 -> 0.19620866 | F42: =H40 -> 0.22538456
A43: λmax = Σ(сумма столбца × приоритет) | B43: =SUMPRODUCT(B41:F41,B42:F42) -> 5.0966151
A44: CI = (λmax − n) / (n − 1) | B44: =(B43-5)/(5-1) -> 0.024153778
A45: RI (случайный индекс, таблица Саати) | B45: 1.12
...

Sheet Альт_C5
A1: Парные сравнения альтернатив по критерию: C5 Интерес команды
A2: Критерий типа B: сравниваем, какая альтернатива лучше по этому критерию.
A4: Эксперт: Пашинский П.
B5: A1 | C5: A2 | D5: A3 | E5: A4 | F5: A5 | G5: Геом. среднее строки | H5: Приоритет (вес)
A6: A1 Дашборд мониторинга инфраструктуры | B6: 1 | C6: 1 | D6: 2 | E6: 1 | F6: 2 | G6: =GEOMEAN(B6:F6) -> 1.3195079 | H6: =G6/SUM(G$6:G$10) -> 0.25349187
A7: A2 Менеджер секретов и конфигов | B7: =1/C6 -> 1 | C7: 1 | D7: 2 | E7: 1 | F7: 2 | G7: =GEOMEAN(B7:F7) -> 1.3195079 | H7: =G7/SUM(G$6:G$10) -> 0.25349187
A8: A3 Трекер техдолга и задач | B8: =1/D6 -> 0.5 | C8: =1/D7 -> 0.5 | D8: 1 | E8: 1 | F8: 1 | G8: =GEOMEAN(B8:F8) -> 0.75785828 | H8: =G8/SUM(G$6:G$10) -> 0.14559285
A9: A4 Бот уведомлений CI/CD | B9: =1/E6 -> 1 | C9: =1/E7 -> 1 | D9: =1/E8 -> 1 | E9: 1 | F9: 2 | G9: =GEOMEAN(B9:F9) -> 1.1486984 | H9: =G9/SUM(G$6:G$10) -> 0.22067749
A10: A5 Каталог внутренней документации | B10: =1/F6 -> 0.5 | C10: =1/F7 -> 0.5 | D10: =1/F8 -> 1 | E10: =1/F9 -> 0.5 | F10: 1 | G10: =GEOMEAN(B10:F10) -> 0.65975396 | H10: =G10/SUM(G$6:G$10) -> 0.12674593
A11: Сумма столбца | B11: =SUM(B6:B10) -> 4 | C11: =SUM(C6:C10) -> 4 | D11: =SUM(D6:D10) -> 7 | E11: =SUM(E6:E10) -> 4.5 | F11: =SUM(F6:F10) -> 8
A12: Приоритет (в строку) | B12: =H6 -> 0.25349187 | C12: =H7 -> 0.25349187 | D12: =H8 -> 0.14559285 | E12: =H9 -> 0.22067749 | F12: =H10 -> 0.12674593
A13: λmax = Σ(сумма столбца × приоритет) | B13: =SUMPRODUCT(B11:F11,B12:F12) -> 5.054101
A14: CI = (λmax − n) / (n − 1) | B14: =(B13-5)/(5-1) -> 0.013525253
A15: RI (случайный индекс, таблица Саати) | B15: 1.12
A16: CR = CI / RI (норма: ≤ 0,10) | B16: =B14/B15 -> 0.012076119
A19: Эксперт: Колесникова А.
B20: A1 | C20: A2 | D20: A3 | E20: A4 | F20: A5 | G20: Геом. среднее строки | H20: Приоритет (вес)
A21: A1 Дашборд мониторинга инфраструктуры | B21: 1 | C21: 2 | D21: 2 | E21: 2 | F21: 2 | G21: =GEOMEAN(B21:F21) -> 1.7411011 | H21: =G21/SUM(G$21:G$25) -> 0.33333333
A22: A2 Менеджер секретов и конфигов | B22: =1/C21 -> 0.5 | C22: 1 | D22: 1 | E22: 1 | F22: 1 | G22: =GEOMEAN(B22:F22) -> 0.87055056 | H22: =G22/SUM(G$21:G$25) -> 0.16666667
A23: A3 Трекер техдолга и задач | B23: =1/D21 -> 0.5 | C23: =1/D22 -> 1 | D23: 1 | E23: 1 | F23: 1 | G23: =GEOMEAN(B23:F23) -> 0.87055056 | H23: =G23/SUM(G$21:G$25) -> 0.16666667
A24: A4 Бот уведомлений CI/CD | B24: =1/E21 -> 0.5 | C24: =1/E22 -> 1 | D24: =1/E23 -> 1 | E24: 1 | F24: 1 | G24: =GEOMEAN(B24:F24) -> 0.87055056 | H24: =G24/SUM(G$21:G$25) -> 0.16666667
A25: A5 Каталог внутренней документации | B25: =1/F21 -> 0.5 | C25: =1/F22 -> 1 | D25: =1/F23 -> 1 | E25: =1/F24 -> 1 | F25: 1 | G25: =GEOMEAN(B25:F25) -> 0.87055056 | H25: =G25/SUM(G$21:G$25) -> 0.16666667
A26: Сумма столбца | B26: =SUM(B21:B25) -> 3 | C26: =SUM(C21:C25) -> 6 | D26: =SUM(D21:D25) -> 6 | E26: =SUM(E21:E25) -> 6 | F26: =SUM(F21:F25) -> 6
A27: Приоритет (в строку) | B27: =H21 -> 0.33333333 | C27: =H22 -> 0.16666667 | D27: =H23 -> 0.16666667 | E27: =H24 -> 0.16666667 | F27: =H25 -> 0.16666667
A28: λmax = Σ(сумма столбца × приоритет) | B28: =SUMPRODUCT(B26:F26,B27:F27) -> 5
A29: CI = (λmax − n) / (n − 1) | B29: =(B28-5)/(5-1) -> 0
A30: RI (случайный индекс, таблица Саати) | B30: 1.12
A31: CR = CI / RI (норма: ≤ 0,10) | B31: =B29/B30 -> 0
A34: Эксперт: Степаненко А.
B35: A1 | C35: A2 | D35: A3 | E35: A4 | F35: A5 | G35: Геом. среднее строки | H35: Приоритет (вес)
A36: A1 Дашборд мониторинга инфраструктуры | B36: 1 | C36: 1 | D36: 2 | E36: 1 | F36: 2 | G36: =GEOMEAN(B36:F36) -> 1.3195079 | H36: =G36/SUM(G$36:G$40) -> 0.25
A37: A2 Менеджер секретов и конфигов | B37: =1/C36 -> 1 | C37: 1 | D37: 2 | E37: 1 | F37: 2 | G37: =GEOMEAN(B37:F37) -> 1.3195079 | H37: =G37/SUM(G$36:G$40) -> 0.25
A38: A3 Трекер техдолга и задач | B38: =1/D36 -> 0.5 | C38: =1/D37 -> 0.5 | D38: 1 | E38: =1/2 -> 0.5 | F38: 1 | G38: =GEOMEAN(B38:F38) -> 0.65975396 | H38: =G38/SUM(G$36:G$40) -> 0.125
A39: A4 Бот уведомлений CI/CD | B39: =1/E36 -> 1 | C39: =1/E37 -> 1 | D39: =1/E38 -> 2 | E39: 1 | F39: 2 | G39: =GEOMEAN(B39:F39) -> 1.3195079 | H39: =G39/SUM(G$36:G$40) -> 0.25
A40: A5 Каталог внутренней документации | B40: =1/F36 -> 0.5 | C40: =1/F37 -> 0.5 | D40: =1/F38 -> 1 | E40: =1/F39 -> 0.5 | F40: 1 | G40: =GEOMEAN(B40:F40) -> 0.65975396 | H40: =G40/SUM(G$36:G$40) -> 0.125
A41: Сумма столбца | B41: =SUM(B36:B40) -> 4 | C41: =SUM(C36:C40) -> 4 | D41: =SUM(D36:D40) -> 8 | E41: =SUM(E36:E40) -> 4 | F41: =SUM(F36:F40) -> 8
A42: Приоритет (в строку) | B42: =H36 -> 0.25 | C42: =H37 -> 0.25 | D42: =H38 -> 0.125 | E42: =H39 -> 0.25 | F42: =H40 -> 0.125
A43: λmax = Σ(сумма столбца × приоритет) | B43: =SUMPRODUCT(B41:F41,B42:F42) -> 5
A44: CI = (λmax − n) / (n − 1) | B44: =(B43-5)/(5-1) -> 0
A45: RI (случайный индекс, таблица Саати) | B45: 1.12
...

Sheet Альт_C6
A1: Парные сравнения альтернатив по критерию: C6 Затраты на поддержку и инфраструктуру
A2: Критерий типа C: сравниваем, какая альтернатива лучше, то есть менее затратная / менее сложная / менее рискованная.
A4: Эксперт: Пашинский П.
B5: A1 | C5: A2 | D5: A3 | E5: A4 | F5: A5 | G5: Геом. среднее строки | H5: Приоритет (вес)
A6: A1 Дашборд мониторинга инфраструктуры | B6: 1 | C6: 1 | D6: =1/2 -> 0.5 | E6: =1/2 -> 0.5 | F6: =1/2 -> 0.5 | G6: =GEOMEAN(B6:F6) -> 0.65975396 | H6: =G6/SUM(G$6:G$10) -> 0.125
A7: A2 Менеджер секретов и конфигов | B7: =1/C6 -> 1 | C7: 1 | D7: =1/2 -> 0.5 | E7: =1/2 -> 0.5 | F7: =1/2 -> 0.5 | G7: =GEOMEAN(B7:F7) -> 0.65975396 | H7: =G7/SUM(G$6:G$10) -> 0.125
A8: A3 Трекер техдолга и задач | B8: =1/D6 -> 2 | C8: =1/D7 -> 2 | D8: 1 | E8: 1 | F8: 1 | G8: =GEOMEAN(B8:F8) -> 1.3195079 | H8: =G8/SUM(G$6:G$10) -> 0.25
A9: A4 Бот уведомлений CI/CD | B9: =1/E6 -> 2 | C9: =1/E7 -> 2 | D9: =1/E8 -> 1 | E9: 1 | F9: 1 | G9: =GEOMEAN(B9:F9) -> 1.3195079 | H9: =G9/SUM(G$6:G$10) -> 0.25
A10: A5 Каталог внутренней документации | B10: =1/F6 -> 2 | C10: =1/F7 -> 2 | D10: =1/F8 -> 1 | E10: =1/F9 -> 1 | F10: 1 | G10: =GEOMEAN(B10:F10) -> 1.3195079 | H10: =G10/SUM(G$6:G$10) -> 0.25
A11: Сумма столбца | B11: =SUM(B6:B10) -> 8 | C11: =SUM(C6:C10) -> 8 | D11: =SUM(D6:D10) -> 4 | E11: =SUM(E6:E10) -> 4 | F11: =SUM(F6:F10) -> 4
A12: Приоритет (в строку) | B12: =H6 -> 0.125 | C12: =H7 -> 0.125 | D12: =H8 -> 0.25 | E12: =H9 -> 0.25 | F12: =H10 -> 0.25
A13: λmax = Σ(сумма столбца × приоритет) | B13: =SUMPRODUCT(B11:F11,B12:F12) -> 5
A14: CI = (λmax − n) / (n − 1) | B14: =(B13-5)/(5-1) -> 0
A15: RI (случайный индекс, таблица Саати) | B15: 1.12
A16: CR = CI / RI (норма: ≤ 0,10) | B16: =B14/B15 -> 0
A19: Эксперт: Колесникова А.
B20: A1 | C20: A2 | D20: A3 | E20: A4 | F20: A5 | G20: Геом. среднее строки | H20: Приоритет (вес)
A21: A1 Дашборд мониторинга инфраструктуры | B21: 1 | C21: 1 | D21: =1/2 -> 0.5 | E21: =1/2 -> 0.5 | F21: 1 | G21: =GEOMEAN(B21:F21) -> 0.75785828 | H21: =G21/SUM(G$21:G$25) -> 0.13827245
A22: A2 Менеджер секретов и конфигов | B22: =1/C21 -> 1 | C22: 1 | D22: =1/2 -> 0.5 | E22: =1/4 -> 0.25 | F22: =1/2 -> 0.5 | G22: =GEOMEAN(B22:F22) -> 0.57434918 | H22: =G22/SUM(G$21:G$25) -> 0.10479092
A23: A3 Трекер техдолга и задач | B23: =1/D21 -> 2 | C23: =1/D22 -> 2 | D23: 1 | E23: =1/2 -> 0.5 | F23: 1 | G23: =GEOMEAN(B23:F23) -> 1.1486984 | H23: =G23/SUM(G$21:G$25) -> 0.20958185
A24: A4 Бот уведомлений CI/CD | B24: =1/E21 -> 2 | C24: =1/E22 -> 4 | D24: =1/E23 -> 2 | E24: 1 | F24: 2 | G24: =GEOMEAN(B24:F24) -> 2 | H24: =G24/SUM(G$21:G$25) -> 0.36490319
A25: A5 Каталог внутренней документации | B25: =1/F21 -> 1 | C25: =1/F22 -> 2 | D25: =1/F23 -> 1 | E25: =1/F24 -> 0.5 | F25: 1 | G25: =GEOMEAN(B25:F25) -> 1 | H25: =G25/SUM(G$21:G$25) -> 0.18245159
A26: Сумма столбца | B26: =SUM(B21:B25) -> 7 | C26: =SUM(C21:C25) -> 10 | D26: =SUM(D21:D25) -> 5 | E26: =SUM(E21:E25) -> 2.75 | F26: =SUM(F21:F25) -> 5.5
A27: Приоритет (в строку) | B27: =H21 -> 0.13827245 | C27: =H22 -> 0.10479092 | D27: =H23 -> 0.20958185 | E27: =H24 -> 0.36490319 | F27: =H25 -> 0.18245159
A28: λmax = Σ(сумма столбца × приоритет) | B28: =SUMPRODUCT(B26:F26,B27:F27) -> 5.0706931
A29: CI = (λmax − n) / (n − 1) | B29: =(B28-5)/(5-1) -> 0.017673286
A30: RI (случайный индекс, таблица Саати) | B30: 1.12
A31: CR = CI / RI (норма: ≤ 0,10) | B31: =B29/B30 -> 0.015779719
A34: Эксперт: Степаненко А.
B35: A1 | C35: A2 | D35: A3 | E35: A4 | F35: A5 | G35: Геом. среднее строки | H35: Приоритет (вес)
A36: A1 Дашборд мониторинга инфраструктуры | B36: 1 | C36: 1 | D36: =1/2 -> 0.5 | E36: =1/2 -> 0.5 | F36: 1 | G36: =GEOMEAN(B36:F36) -> 0.75785828 | H36: =G36/SUM(G$36:G$40) -> 0.14220111
A37: A2 Менеджер секретов и конфигов | B37: =1/C36 -> 1 | C37: 1 | D37: =1/2 -> 0.5 | E37: =1/3 -> 0.33333333 | F37: =1/2 -> 0.5 | G37: =GEOMEAN(B37:F37) -> 0.60836434 | H37: =G37/SUM(G$36:G$40) -> 0.11415074
A38: A3 Трекер техдолга и задач | B38: =1/D36 -> 2 | C38: =1/D37 -> 2 | D38: 1 | E38: 1 | F38: 1 | G38: =GEOMEAN(B38:F38) -> 1.3195079 | H38: =G38/SUM(G$36:G$40) -> 0.2475865
A39: A4 Бот уведомлений CI/CD | B39: =1/E36 -> 2 | C39: =1/E37 -> 3 | D39: =1/E38 -> 1 | E39: 1 | F39: 2 | G39: =GEOMEAN(B39:F39) -> 1.6437518 | H39: =G39/SUM(G$36:G$40) -> 0.30842617
A40: A5 Каталог внутренней документации | B40: =1/F36 -> 1 | C40: =1/F37 -> 2 | D40: =1/F38 -> 1 | E40: =1/F39 -> 0.5 | F40: 1 | G40: =GEOMEAN(B40:F40) -> 1 | H40: =G40/SUM(G$36:G$40) -> 0.18763548
A41: Сумма столбца | B41: =SUM(B36:B40) -> 7 | C41: =SUM(C36:C40) -> 9 | D41: =SUM(D36:D40) -> 4 | E41: =SUM(E36:E40) -> 3.3333333 | F41: =SUM(F36:F40) -> 5.5
A42: Приоритет (в строку) | B42: =H36 -> 0.14220111 | C42: =H37 -> 0.11415074 | D42: =H38 -> 0.2475865 | E42: =H39 -> 0.30842617 | F42: =H40 -> 0.18763548
A43: λmax = Σ(сумма столбца × приоритет) | B43: =SUMPRODUCT(B41:F41,B42:F42) -> 5.0731928
A44: CI = (λmax − n) / (n − 1) | B44: =(B43-5)/(5-1) -> 0.018298195
A45: RI (случайный индекс, таблица Саати) | B45: 1.12
...
